11:09:57 [WARNING] PyNaCl is not installed, voice will NOT be supported
11:09:57 [DEBUG] on_ready has successfully been registered as an event
11:09:57 [DEBUG] Using proactor: IocpProactor
11:09:57 [INFO] logging in using static token
11:09:58 [INFO] Shard ID None has connected to Gateway (Session ID: 13f6c2d8965eca12df208fa9a3b54eab).
11:21:05 [DEBUG] Running subprocess command: C:\Python313\python.exe c:\Programs\SE Modding\DSV Modding\DSV-The_Maw\DataVisuals\graph.py --weapon_one M240 Cyclone Strike Cannon --weapon_two M600 Typhoon Strike Cannon --trait_one Shots in Clip --trait_two Effective Integrity
11:22:43 [DEBUG] Running subprocess command: C:\Python313\python.exe c:\Programs\SE Modding\DSV Modding\DSV-The_Maw\DataVisuals\graph.py --weapon_one M240 Cyclone Strike Cannon --weapon_two M600 Typhoon Strike Cannon --trait_one Shots in Clip --trait_two Effective Integrity
11:24:59 [DEBUG] Running subprocess command: C:\Python313\python.exe c:\Programs\SE Modding\DSV Modding\DSV-The_Maw\DataVisuals\graph.py --weapon_one M240 Cyclone Strike Cannon --weapon_two M600 Typhoon Strike Cannon --trait_one Shots in Clip --trait_two Effective Integrity
11:26:31 [DEBUG] Running subprocess command: C:\Python313\python.exe c:\Programs\SE Modding\DSV Modding\DSV-The_Maw\DataVisuals\graph.py --weapon_one M240 Cyclone Strike Cannon --weapon_two M600 Typhoon Strike Cannon --trait_one Shots in Clip --trait_two Effective Integrity
11:27:14 [DEBUG] Running subprocess command: C:\Python313\python.exe c:\Programs\SE Modding\DSV Modding\DSV-The_Maw\DataVisuals\graph.py --weapon_one M240 Cyclone Strike Cannon --weapon_two M600 Typhoon Strike Cannon --trait_one Shots in Clip --trait_two Effective Integrity
11:27:41 [DEBUG] Running subprocess command: C:\Python313\python.exe c:\Programs\SE Modding\DSV Modding\DSV-The_Maw\DataVisuals\graph.py --weapon_one M240 Cyclone Strike Cannon --weapon_two M600 Typhoon Strike Cannon --trait_one Shots in Clip --trait_two Effective Integrity
11:28:21 [DEBUG] Running subprocess command: C:\Python313\python.exe c:\Programs\SE Modding\DSV Modding\DSV-The_Maw\DataVisuals\graph.py --weapon_one M240 Cyclone Strike Cannon --weapon_two M600 Typhoon Strike Cannon --trait_one Shots in Clip --trait_two Effective Integrity
11:29:10 [DEBUG] Running subprocess command: C:\Python313\python.exe c:\Programs\SE Modding\DSV Modding\DSV-The_Maw\DataVisuals\graph.py --weapon_one M240 Cyclone Strike Cannon --weapon_two M600 Typhoon Strike Cannon --trait_one Shots in Clip --trait_two Effective Integrity
11:30:35 [DEBUG] Running subprocess command: C:\Python313\python.exe c:\Programs\SE Modding\DSV Modding\DSV-The_Maw\DataVisuals\graph.py --weapon_one M240 Cyclone Strike Cannon --weapon_two M600 Typhoon Strike Cannon --trait_one Shots in Clip --trait_two Effective Integrity
11:33:48 [DEBUG] Running subprocess command: C:\Python313\python.exe c:\Programs\SE Modding\DSV Modding\DSV-The_Maw\DataVisuals\graph.py --weapon_one M240 Cyclone Strike Cannon --weapon_two M600 Typhoon Strike Cannon --trait_one Points --trait_two Effective Integrity
11:34:26 [DEBUG] Running subprocess command: C:\Python313\python.exe c:\Programs\SE Modding\DSV Modding\DSV-The_Maw\DataVisuals\graph.py --weapon_one M240 Cyclone Strike Cannon --weapon_two M600 Typhoon Strike Cannon --trait_one Points --trait_two Effective Integrity
11:35:38 [DEBUG] Running subprocess command: C:\Python313\python.exe c:\Programs\SE Modding\DSV Modding\DSV-The_Maw\DataVisuals\graph.py --weapon_one M240 Cyclone Strike Cannon --weapon_two M600 Typhoon Strike Cannon --trait_one Points --trait_two Effective Integrity
11:36:30 [DEBUG] Running subprocess command: C:\Python313\python.exe c:\Programs\SE Modding\DSV Modding\DSV-The_Maw\DataVisuals\graph.py --weapon_one M240 Cyclone Strike Cannon --weapon_two M600 Typhoon Strike Cannon --trait_one Points
11:36:31 [ERROR] Ignoring exception in command 'compare_specific_weapons'
Traceback (most recent call last):
  File "C:\Users\Skye\AppData\Roaming\Python\Python313\site-packages\discord\app_commands\commands.py", line 858, in _do_call
    return await self._callback(interaction, **params)  # type: ignore
           ^^^^^^^^^^^^^^^^^^^^^^^^^^^^^^^^^^^^^^^^^^^
  File "c:\Programs\SE Modding\DSV Modding\DSV-The_Maw\DataVisuals\bot.py", line 112, in create_graph
    await asyncio.wait_for(process(), timeout=30)
  File "C:\Python313\Lib\asyncio\tasks.py", line 507, in wait_for
    return await fut
           ^^^^^^^^^
  File "c:\Programs\SE Modding\DSV Modding\DSV-The_Maw\DataVisuals\bot.py", line 108, in process
    raise RuntimeError(f"Graph Script failed with code {result.returncode}")
RuntimeError: Graph Script failed with code 1

The above exception was the direct cause of the following exception:

Traceback (most recent call last):
  File "C:\Users\Skye\AppData\Roaming\Python\Python313\site-packages\discord\app_commands\tree.py", line 1310, in _call
    await command._invoke_with_namespace(interaction, namespace)
  File "C:\Users\Skye\AppData\Roaming\Python\Python313\site-packages\discord\app_commands\commands.py", line 883, in _invoke_with_namespace
    return await self._do_call(interaction, transformed_values)
           ^^^^^^^^^^^^^^^^^^^^^^^^^^^^^^^^^^^^^^^^^^^^^^^^^^^^
  File "C:\Users\Skye\AppData\Roaming\Python\Python313\site-packages\discord\app_commands\commands.py", line 876, in _do_call
    raise CommandInvokeError(self, e) from e
discord.app_commands.errors.CommandInvokeError: Command 'compare_specific_weapons' raised an exception: RuntimeError: Graph Script failed with code 1
11:39:18 [DEBUG] Running subprocess command: C:\Python313\python.exe c:\Programs\SE Modding\DSV Modding\DSV-The_Maw\DataVisuals\graph.py --weapon_one M240 Cyclone Strike Cannon --weapon_two M600 Typhoon Strike Cannon --trait_one Points
11:40:20 [DEBUG] Running subprocess command: C:\Python313\python.exe c:\Programs\SE Modding\DSV Modding\DSV-The_Maw\DataVisuals\graph.py --weapon_one M240 Cyclone Strike Cannon --weapon_two M600 Typhoon Strike Cannon --trait_one Points
